{"name": "test_xfail_expected_failure", "status": "skipped", "statusDetails": {"message": "AssertionError: assert False", "trace": "@pytest.mark.xfail(condition=lambda: True, reason='this test is expecting failure')\n    def test_xfail_expected_failure():\n        \"\"\"this test is an xfail that will be marked as expected failure\"\"\"\n>       assert False\nE       assert False\n\nAllureTestReports.py:26: AssertionError"}, "description": "this test is an xfail that will be marked as expected failure", "start": 1580204610533, "stop": 1580204610534, "uuid": "ad1fc5ba-6d3b-411d-8924-c1e9d480e034", "historyId": "0ad0cdf8b680be19df870377629b9af8", "testCaseId": "aeabe0ef4f21ab4c6e4c3757157979e5", "fullName": "AllureTestReports#test_xfail_expected_failure", "labels": [{"name": "suite", "value": "AllureTestReports"}, {"name": "host", "value": "USBLRNPAVANKUM1"}, {"name": "thread", "value": "16720-MainThread"}, {"name": "framework", "value": "pytest"}, {"name": "language", "value": "cpython3"}, {"name": "package", "value": "AllureTestReports"}]}